[2024-06-24T01:02:41.039+0000] {local_task_job_runner.py:120} INFO - ::group::Pre task execution logs
[2024-06-24T01:02:41.058+0000] {taskinstance.py:2076} INFO - Dependencies all met for dep_context=non-requeueable deps ti=<TaskInstance: decrypt_transform_dag.decrypt_transform_and_upload manual__2024-06-24T01:02:34.352407+00:00 [queued]>
[2024-06-24T01:02:41.070+0000] {taskinstance.py:2076} INFO - Dependencies all met for dep_context=requeueable deps ti=<TaskInstance: decrypt_transform_dag.decrypt_transform_and_upload manual__2024-06-24T01:02:34.352407+00:00 [queued]>
[2024-06-24T01:02:41.071+0000] {taskinstance.py:2306} INFO - Starting attempt 1 of 2
[2024-06-24T01:02:41.087+0000] {taskinstance.py:2330} INFO - Executing <Task(PythonOperator): decrypt_transform_and_upload> on 2024-06-24 01:02:34.352407+00:00
[2024-06-24T01:02:41.105+0000] {warnings.py:112} WARNING - /home/***/.local/lib/python3.12/site-packages/***/task/task_runner/standard_task_runner.py:61: DeprecationWarning: This process (pid=738) is multi-threaded, use of fork() may lead to deadlocks in the child.
  pid = os.fork()

[2024-06-24T01:02:41.107+0000] {standard_task_runner.py:63} INFO - Started process 792 to run task
[2024-06-24T01:02:41.105+0000] {standard_task_runner.py:90} INFO - Running: ['***', 'tasks', 'run', 'decrypt_transform_dag', 'decrypt_transform_and_upload', 'manual__2024-06-24T01:02:34.352407+00:00', '--job-id', '162', '--raw', '--subdir', 'DAGS_FOLDER/transformar_desencriptar.py', '--cfg-path', '/tmp/tmpzmvdoivn']
[2024-06-24T01:02:41.109+0000] {standard_task_runner.py:91} INFO - Job 162: Subtask decrypt_transform_and_upload
[2024-06-24T01:02:41.161+0000] {task_command.py:426} INFO - Running <TaskInstance: decrypt_transform_dag.decrypt_transform_and_upload manual__2024-06-24T01:02:34.352407+00:00 [running]> on host 61fcf08f48e3
[2024-06-24T01:02:41.266+0000] {taskinstance.py:2648} INFO - Exporting env vars: AIRFLOW_CTX_DAG_OWNER='***' AIRFLOW_CTX_DAG_ID='decrypt_transform_dag' AIRFLOW_CTX_TASK_ID='decrypt_transform_and_upload' AIRFLOW_CTX_EXECUTION_DATE='2024-06-24T01:02:34.352407+00:00' AIRFLOW_CTX_TRY_NUMBER='1' AIRFLOW_CTX_DAG_RUN_ID='manual__2024-06-24T01:02:34.352407+00:00'
[2024-06-24T01:02:41.268+0000] {taskinstance.py:430} INFO - ::endgroup::
[2024-06-24T01:02:41.292+0000] {transformar_desencriptar.py:60} INFO - Starting decryption and transformation process...
[2024-06-24T01:02:41.301+0000] {connection.py:274} WARNING - Connection schemes (type: google_cloud_platform) shall not contain '_' according to RFC3986.
[2024-06-24T01:02:41.304+0000] {base.py:84} INFO - Using connection ID 'google_cloud_default' for task execution.
[2024-06-24T01:02:42.036+0000] {gcs.py:354} ERROR - Download attempt of object: datasets/athletes.csv.enc from golden-cheetah-datasets has failed. Attempt: 0, max 1.
[2024-06-24T01:02:42.037+0000] {transformar_desencriptar.py:97} ERROR - An error occurred during the decryption, transformation and upload process
Traceback (most recent call last):
  File "/home/airflow/.local/lib/python3.12/site-packages/google/cloud/storage/blob.py", line 4362, in _prep_and_do_download
    self._do_download(
  File "/home/airflow/.local/lib/python3.12/site-packages/google/cloud/storage/blob.py", line 1017, in _do_download
    response = download.consume(transport, timeout=timeout)
               ^^^^^^^^^^^^^^^^^^^^^^^^^^^^^^^^^^^^^^^^^^^^
  File "/home/airflow/.local/lib/python3.12/site-packages/google/resumable_media/requests/download.py", line 237, in consume
    return _request_helpers.wait_and_retry(
           ^^^^^^^^^^^^^^^^^^^^^^^^^^^^^^^^
  File "/home/airflow/.local/lib/python3.12/site-packages/google/resumable_media/requests/_request_helpers.py", line 155, in wait_and_retry
    response = func()
               ^^^^^^
  File "/home/airflow/.local/lib/python3.12/site-packages/google/resumable_media/requests/download.py", line 219, in retriable_request
    self._process_response(result)
  File "/home/airflow/.local/lib/python3.12/site-packages/google/resumable_media/_download.py", line 188, in _process_response
    _helpers.require_status_code(
  File "/home/airflow/.local/lib/python3.12/site-packages/google/resumable_media/_helpers.py", line 108, in require_status_code
    raise common.InvalidResponse(
google.resumable_media.common.InvalidResponse: ('Request failed with status code', 404, 'Expected one of', 200, 206)

During handling of the above exception, another exception occurred:

Traceback (most recent call last):
  File "/opt/airflow/dags/transformar_desencriptar.py", line 66, in task_decrypt_transform_and_upload
    ciphertext = gcs_hook.download(bucket_name, source_blob)
                 ^^^^^^^^^^^^^^^^^^^^^^^^^^^^^^^^^^^^^^^^^^^
  File "/home/airflow/.local/lib/python3.12/site-packages/airflow/providers/google/cloud/hooks/gcs.py", line 350, in download
    return blob.download_as_bytes()
           ^^^^^^^^^^^^^^^^^^^^^^^^
  File "/home/airflow/.local/lib/python3.12/site-packages/google/cloud/storage/blob.py", line 1435, in download_as_bytes
    self._prep_and_do_download(
  File "/home/airflow/.local/lib/python3.12/site-packages/google/cloud/storage/blob.py", line 4375, in _prep_and_do_download
    _raise_from_invalid_response(exc)
  File "/home/airflow/.local/lib/python3.12/site-packages/google/cloud/storage/blob.py", line 4847, in _raise_from_invalid_response
    raise exceptions.from_http_status(response.status_code, message, response=response)
google.api_core.exceptions.NotFound: 404 GET https://storage.googleapis.com/download/storage/v1/b/golden-cheetah-datasets/o/datasets%2Fathletes.csv.enc?alt=media: No such object: golden-cheetah-datasets/datasets/athletes.csv.enc: ('Request failed with status code', 404, 'Expected one of', <HTTPStatus.OK: 200>, <HTTPStatus.PARTIAL_CONTENT: 206>)
[2024-06-24T01:02:42.054+0000] {taskinstance.py:441} INFO - ::group::Post task execution logs
[2024-06-24T01:02:42.055+0000] {taskinstance.py:2905} ERROR - Task failed with exception
Traceback (most recent call last):
  File "/home/airflow/.local/lib/python3.12/site-packages/google/cloud/storage/blob.py", line 4362, in _prep_and_do_download
    self._do_download(
  File "/home/airflow/.local/lib/python3.12/site-packages/google/cloud/storage/blob.py", line 1017, in _do_download
    response = download.consume(transport, timeout=timeout)
               ^^^^^^^^^^^^^^^^^^^^^^^^^^^^^^^^^^^^^^^^^^^^
  File "/home/airflow/.local/lib/python3.12/site-packages/google/resumable_media/requests/download.py", line 237, in consume
    return _request_helpers.wait_and_retry(
           ^^^^^^^^^^^^^^^^^^^^^^^^^^^^^^^^
  File "/home/airflow/.local/lib/python3.12/site-packages/google/resumable_media/requests/_request_helpers.py", line 155, in wait_and_retry
    response = func()
               ^^^^^^
  File "/home/airflow/.local/lib/python3.12/site-packages/google/resumable_media/requests/download.py", line 219, in retriable_request
    self._process_response(result)
  File "/home/airflow/.local/lib/python3.12/site-packages/google/resumable_media/_download.py", line 188, in _process_response
    _helpers.require_status_code(
  File "/home/airflow/.local/lib/python3.12/site-packages/google/resumable_media/_helpers.py", line 108, in require_status_code
    raise common.InvalidResponse(
google.resumable_media.common.InvalidResponse: ('Request failed with status code', 404, 'Expected one of', 200, 206)

During handling of the above exception, another exception occurred:

Traceback (most recent call last):
  File "/home/airflow/.local/lib/python3.12/site-packages/airflow/models/taskinstance.py", line 465, in _execute_task
    result = _execute_callable(context=context, **execute_callable_kwargs)
             ^^^^^^^^^^^^^^^^^^^^^^^^^^^^^^^^^^^^^^^^^^^^^^^^^^^^^^^^^^^^^
  File "/home/airflow/.local/lib/python3.12/site-packages/airflow/models/taskinstance.py", line 432, in _execute_callable
    return execute_callable(context=context, **execute_callable_kwargs)
           ^^^^^^^^^^^^^^^^^^^^^^^^^^^^^^^^^^^^^^^^^^^^^^^^^^^^^^^^^^^^
  File "/home/airflow/.local/lib/python3.12/site-packages/airflow/models/baseoperator.py", line 401, in wrapper
    return func(self, *args, **kwargs)
           ^^^^^^^^^^^^^^^^^^^^^^^^^^^
  File "/home/airflow/.local/lib/python3.12/site-packages/airflow/operators/python.py", line 235, in execute
    return_value = self.execute_callable()
                   ^^^^^^^^^^^^^^^^^^^^^^^
  File "/home/airflow/.local/lib/python3.12/site-packages/airflow/operators/python.py", line 252, in execute_callable
    return self.python_callable(*self.op_args, **self.op_kwargs)
           ^^^^^^^^^^^^^^^^^^^^^^^^^^^^^^^^^^^^^^^^^^^^^^^^^^^^^
  File "/opt/airflow/dags/transformar_desencriptar.py", line 66, in task_decrypt_transform_and_upload
    ciphertext = gcs_hook.download(bucket_name, source_blob)
                 ^^^^^^^^^^^^^^^^^^^^^^^^^^^^^^^^^^^^^^^^^^^
  File "/home/airflow/.local/lib/python3.12/site-packages/airflow/providers/google/cloud/hooks/gcs.py", line 350, in download
    return blob.download_as_bytes()
           ^^^^^^^^^^^^^^^^^^^^^^^^
  File "/home/airflow/.local/lib/python3.12/site-packages/google/cloud/storage/blob.py", line 1435, in download_as_bytes
    self._prep_and_do_download(
  File "/home/airflow/.local/lib/python3.12/site-packages/google/cloud/storage/blob.py", line 4375, in _prep_and_do_download
    _raise_from_invalid_response(exc)
  File "/home/airflow/.local/lib/python3.12/site-packages/google/cloud/storage/blob.py", line 4847, in _raise_from_invalid_response
    raise exceptions.from_http_status(response.status_code, message, response=response)
google.api_core.exceptions.NotFound: 404 GET https://storage.googleapis.com/download/storage/v1/b/golden-cheetah-datasets/o/datasets%2Fathletes.csv.enc?alt=media: No such object: golden-cheetah-datasets/datasets/athletes.csv.enc: ('Request failed with status code', 404, 'Expected one of', <HTTPStatus.OK: 200>, <HTTPStatus.PARTIAL_CONTENT: 206>)
[2024-06-24T01:02:42.070+0000] {taskinstance.py:1206} INFO - Marking task as UP_FOR_RETRY. dag_id=decrypt_transform_dag, task_id=decrypt_transform_and_upload, run_id=manual__2024-06-24T01:02:34.352407+00:00, execution_date=20240624T010234, start_date=20240624T010241, end_date=20240624T010242
[2024-06-24T01:02:42.093+0000] {standard_task_runner.py:110} ERROR - Failed to execute job 162 for task decrypt_transform_and_upload (404 GET https://storage.googleapis.com/download/storage/v1/b/golden-cheetah-datasets/o/datasets%2Fathletes.csv.enc?alt=media: No such object: golden-cheetah-datasets/datasets/athletes.csv.enc: ('Request failed with status code', 404, 'Expected one of', <HTTPStatus.OK: 200>, <HTTPStatus.PARTIAL_CONTENT: 206>); 792)
[2024-06-24T01:02:42.126+0000] {local_task_job_runner.py:240} INFO - Task exited with return code 1
[2024-06-24T01:02:42.150+0000] {taskinstance.py:3503} INFO - 0 downstream tasks scheduled from follow-on schedule check
[2024-06-24T01:02:42.153+0000] {local_task_job_runner.py:222} INFO - ::endgroup::
