[2024-06-24T04:49:40.911+0000] {local_task_job_runner.py:120} INFO - ::group::Pre task execution logs
[2024-06-24T04:49:40.943+0000] {taskinstance.py:2076} INFO - Dependencies all met for dep_context=non-requeueable deps ti=<TaskInstance: encryption_dag.encrypt_and_upload manual__2024-06-24T04:49:19.710927+00:00 [queued]>
[2024-06-24T04:49:40.961+0000] {taskinstance.py:2076} INFO - Dependencies all met for dep_context=requeueable deps ti=<TaskInstance: encryption_dag.encrypt_and_upload manual__2024-06-24T04:49:19.710927+00:00 [queued]>
[2024-06-24T04:49:40.963+0000] {taskinstance.py:2306} INFO - Starting attempt 1 of 2
[2024-06-24T04:49:41.001+0000] {taskinstance.py:2330} INFO - Executing <Task(PythonOperator): encrypt_and_upload> on 2024-06-24 04:49:19.710927+00:00
[2024-06-24T04:49:41.029+0000] {warnings.py:112} WARNING - /home/***/.local/lib/python3.12/site-packages/***/task/task_runner/standard_task_runner.py:61: DeprecationWarning: This process (pid=808) is multi-threaded, use of fork() may lead to deadlocks in the child.
  pid = os.fork()

[2024-06-24T04:49:41.033+0000] {standard_task_runner.py:63} INFO - Started process 821 to run task
[2024-06-24T04:49:41.033+0000] {standard_task_runner.py:90} INFO - Running: ['***', 'tasks', 'run', 'encryption_dag', 'encrypt_and_upload', 'manual__2024-06-24T04:49:19.710927+00:00', '--job-id', '217', '--raw', '--subdir', 'DAGS_FOLDER/encryption_dag.py', '--cfg-path', '/tmp/tmpzt0qb539']
[2024-06-24T04:49:41.046+0000] {standard_task_runner.py:91} INFO - Job 217: Subtask encrypt_and_upload
[2024-06-24T04:49:42.614+0000] {task_command.py:426} INFO - Running <TaskInstance: encryption_dag.encrypt_and_upload manual__2024-06-24T04:49:19.710927+00:00 [running]> on host 4e5646ae0bec
[2024-06-24T04:49:42.786+0000] {taskinstance.py:2648} INFO - Exporting env vars: AIRFLOW_CTX_DAG_OWNER='***' AIRFLOW_CTX_DAG_ID='encryption_dag' AIRFLOW_CTX_TASK_ID='encrypt_and_upload' AIRFLOW_CTX_EXECUTION_DATE='2024-06-24T04:49:19.710927+00:00' AIRFLOW_CTX_TRY_NUMBER='1' AIRFLOW_CTX_DAG_RUN_ID='manual__2024-06-24T04:49:19.710927+00:00'
[2024-06-24T04:49:42.790+0000] {taskinstance.py:430} INFO - ::endgroup::
[2024-06-24T04:49:42.817+0000] {encryption_dag.py:44} INFO - Starting encryption process...
[2024-06-24T04:49:42.835+0000] {connection.py:274} WARNING - Connection schemes (type: google_cloud_platform) shall not contain '_' according to RFC3986.
[2024-06-24T04:49:42.840+0000] {base.py:84} INFO - Using connection ID 'google_cloud_default' for task execution.
[2024-06-24T04:49:45.212+0000] {gcs.py:354} ERROR - Download attempt of object: datasets/athletes.csv from golden-cheetah-datasets has failed. Attempt: 0, max 1.
[2024-06-24T04:49:45.216+0000] {encryption_dag.py:66} ERROR - An error occurred during the encryption and upload process
Traceback (most recent call last):
  File "/home/airflow/.local/lib/python3.12/site-packages/google/cloud/storage/blob.py", line 4362, in _prep_and_do_download
    self._do_download(
  File "/home/airflow/.local/lib/python3.12/site-packages/google/cloud/storage/blob.py", line 1017, in _do_download
    response = download.consume(transport, timeout=timeout)
               ^^^^^^^^^^^^^^^^^^^^^^^^^^^^^^^^^^^^^^^^^^^^
  File "/home/airflow/.local/lib/python3.12/site-packages/google/resumable_media/requests/download.py", line 237, in consume
    return _request_helpers.wait_and_retry(
           ^^^^^^^^^^^^^^^^^^^^^^^^^^^^^^^^
  File "/home/airflow/.local/lib/python3.12/site-packages/google/resumable_media/requests/_request_helpers.py", line 155, in wait_and_retry
    response = func()
               ^^^^^^
  File "/home/airflow/.local/lib/python3.12/site-packages/google/resumable_media/requests/download.py", line 219, in retriable_request
    self._process_response(result)
  File "/home/airflow/.local/lib/python3.12/site-packages/google/resumable_media/_download.py", line 188, in _process_response
    _helpers.require_status_code(
  File "/home/airflow/.local/lib/python3.12/site-packages/google/resumable_media/_helpers.py", line 108, in require_status_code
    raise common.InvalidResponse(
google.resumable_media.common.InvalidResponse: ('Request failed with status code', 404, 'Expected one of', 200, 206)

During handling of the above exception, another exception occurred:

Traceback (most recent call last):
  File "/opt/airflow/dags/encryption_dag.py", line 50, in task_encrypt_and_upload
    source_data = gcs_hook.download(bucket_name, source_blob)
                  ^^^^^^^^^^^^^^^^^^^^^^^^^^^^^^^^^^^^^^^^^^^
  File "/home/airflow/.local/lib/python3.12/site-packages/airflow/providers/google/cloud/hooks/gcs.py", line 350, in download
    return blob.download_as_bytes()
           ^^^^^^^^^^^^^^^^^^^^^^^^
  File "/home/airflow/.local/lib/python3.12/site-packages/google/cloud/storage/blob.py", line 1435, in download_as_bytes
    self._prep_and_do_download(
  File "/home/airflow/.local/lib/python3.12/site-packages/google/cloud/storage/blob.py", line 4375, in _prep_and_do_download
    _raise_from_invalid_response(exc)
  File "/home/airflow/.local/lib/python3.12/site-packages/google/cloud/storage/blob.py", line 4847, in _raise_from_invalid_response
    raise exceptions.from_http_status(response.status_code, message, response=response)
google.api_core.exceptions.NotFound: 404 GET https://storage.googleapis.com/download/storage/v1/b/golden-cheetah-datasets/o/datasets%2Fathletes.csv?alt=media: No such object: golden-cheetah-datasets/datasets/athletes.csv: ('Request failed with status code', 404, 'Expected one of', <HTTPStatus.OK: 200>, <HTTPStatus.PARTIAL_CONTENT: 206>)
[2024-06-24T04:49:45.235+0000] {taskinstance.py:441} INFO - ::group::Post task execution logs
[2024-06-24T04:49:45.236+0000] {taskinstance.py:2905} ERROR - Task failed with exception
Traceback (most recent call last):
  File "/home/airflow/.local/lib/python3.12/site-packages/google/cloud/storage/blob.py", line 4362, in _prep_and_do_download
    self._do_download(
  File "/home/airflow/.local/lib/python3.12/site-packages/google/cloud/storage/blob.py", line 1017, in _do_download
    response = download.consume(transport, timeout=timeout)
               ^^^^^^^^^^^^^^^^^^^^^^^^^^^^^^^^^^^^^^^^^^^^
  File "/home/airflow/.local/lib/python3.12/site-packages/google/resumable_media/requests/download.py", line 237, in consume
    return _request_helpers.wait_and_retry(
           ^^^^^^^^^^^^^^^^^^^^^^^^^^^^^^^^
  File "/home/airflow/.local/lib/python3.12/site-packages/google/resumable_media/requests/_request_helpers.py", line 155, in wait_and_retry
    response = func()
               ^^^^^^
  File "/home/airflow/.local/lib/python3.12/site-packages/google/resumable_media/requests/download.py", line 219, in retriable_request
    self._process_response(result)
  File "/home/airflow/.local/lib/python3.12/site-packages/google/resumable_media/_download.py", line 188, in _process_response
    _helpers.require_status_code(
  File "/home/airflow/.local/lib/python3.12/site-packages/google/resumable_media/_helpers.py", line 108, in require_status_code
    raise common.InvalidResponse(
google.resumable_media.common.InvalidResponse: ('Request failed with status code', 404, 'Expected one of', 200, 206)

During handling of the above exception, another exception occurred:

Traceback (most recent call last):
  File "/home/airflow/.local/lib/python3.12/site-packages/airflow/models/taskinstance.py", line 465, in _execute_task
    result = _execute_callable(context=context, **execute_callable_kwargs)
             ^^^^^^^^^^^^^^^^^^^^^^^^^^^^^^^^^^^^^^^^^^^^^^^^^^^^^^^^^^^^^
  File "/home/airflow/.local/lib/python3.12/site-packages/airflow/models/taskinstance.py", line 432, in _execute_callable
    return execute_callable(context=context, **execute_callable_kwargs)
           ^^^^^^^^^^^^^^^^^^^^^^^^^^^^^^^^^^^^^^^^^^^^^^^^^^^^^^^^^^^^
  File "/home/airflow/.local/lib/python3.12/site-packages/airflow/models/baseoperator.py", line 401, in wrapper
    return func(self, *args, **kwargs)
           ^^^^^^^^^^^^^^^^^^^^^^^^^^^
  File "/home/airflow/.local/lib/python3.12/site-packages/airflow/operators/python.py", line 235, in execute
    return_value = self.execute_callable()
                   ^^^^^^^^^^^^^^^^^^^^^^^
  File "/home/airflow/.local/lib/python3.12/site-packages/airflow/operators/python.py", line 252, in execute_callable
    return self.python_callable(*self.op_args, **self.op_kwargs)
           ^^^^^^^^^^^^^^^^^^^^^^^^^^^^^^^^^^^^^^^^^^^^^^^^^^^^^
  File "/opt/airflow/dags/encryption_dag.py", line 50, in task_encrypt_and_upload
    source_data = gcs_hook.download(bucket_name, source_blob)
                  ^^^^^^^^^^^^^^^^^^^^^^^^^^^^^^^^^^^^^^^^^^^
  File "/home/airflow/.local/lib/python3.12/site-packages/airflow/providers/google/cloud/hooks/gcs.py", line 350, in download
    return blob.download_as_bytes()
           ^^^^^^^^^^^^^^^^^^^^^^^^
  File "/home/airflow/.local/lib/python3.12/site-packages/google/cloud/storage/blob.py", line 1435, in download_as_bytes
    self._prep_and_do_download(
  File "/home/airflow/.local/lib/python3.12/site-packages/google/cloud/storage/blob.py", line 4375, in _prep_and_do_download
    _raise_from_invalid_response(exc)
  File "/home/airflow/.local/lib/python3.12/site-packages/google/cloud/storage/blob.py", line 4847, in _raise_from_invalid_response
    raise exceptions.from_http_status(response.status_code, message, response=response)
google.api_core.exceptions.NotFound: 404 GET https://storage.googleapis.com/download/storage/v1/b/golden-cheetah-datasets/o/datasets%2Fathletes.csv?alt=media: No such object: golden-cheetah-datasets/datasets/athletes.csv: ('Request failed with status code', 404, 'Expected one of', <HTTPStatus.OK: 200>, <HTTPStatus.PARTIAL_CONTENT: 206>)
[2024-06-24T04:49:45.251+0000] {taskinstance.py:1206} INFO - Marking task as UP_FOR_RETRY. dag_id=encryption_dag, task_id=encrypt_and_upload, run_id=manual__2024-06-24T04:49:19.710927+00:00, execution_date=20240624T044919, start_date=20240624T044940, end_date=20240624T044945
[2024-06-24T04:49:45.268+0000] {standard_task_runner.py:110} ERROR - Failed to execute job 217 for task encrypt_and_upload (404 GET https://storage.googleapis.com/download/storage/v1/b/golden-cheetah-datasets/o/datasets%2Fathletes.csv?alt=media: No such object: golden-cheetah-datasets/datasets/athletes.csv: ('Request failed with status code', 404, 'Expected one of', <HTTPStatus.OK: 200>, <HTTPStatus.PARTIAL_CONTENT: 206>); 821)
[2024-06-24T04:49:45.305+0000] {local_task_job_runner.py:240} INFO - Task exited with return code 1
[2024-06-24T04:49:45.321+0000] {taskinstance.py:3503} INFO - 0 downstream tasks scheduled from follow-on schedule check
[2024-06-24T04:49:45.325+0000] {local_task_job_runner.py:222} INFO - ::endgroup::
