[2024-06-23T02:39:36.209+0000] {local_task_job_runner.py:120} INFO - ::group::Pre task execution logs
[2024-06-23T02:39:36.232+0000] {taskinstance.py:2076} INFO - Dependencies all met for dep_context=non-requeueable deps ti=<TaskInstance: etl_pipeline_dag.load_to_final_data manual__2024-06-23T02:38:51.935536+00:00 [queued]>
[2024-06-23T02:39:36.242+0000] {taskinstance.py:2076} INFO - Dependencies all met for dep_context=requeueable deps ti=<TaskInstance: etl_pipeline_dag.load_to_final_data manual__2024-06-23T02:38:51.935536+00:00 [queued]>
[2024-06-23T02:39:36.243+0000] {taskinstance.py:2306} INFO - Starting attempt 1 of 1
[2024-06-23T02:39:36.257+0000] {taskinstance.py:2330} INFO - Executing <Task(BigQueryInsertJobOperator): load_to_final_data> on 2024-06-23 02:38:51.935536+00:00
[2024-06-23T02:39:36.267+0000] {warnings.py:112} WARNING - /home/***/.local/lib/python3.12/site-packages/***/task/task_runner/standard_task_runner.py:61: DeprecationWarning: This process (pid=4642) is multi-threaded, use of fork() may lead to deadlocks in the child.
  pid = os.fork()

[2024-06-23T02:39:36.269+0000] {standard_task_runner.py:63} INFO - Started process 4644 to run task
[2024-06-23T02:39:36.269+0000] {standard_task_runner.py:90} INFO - Running: ['***', 'tasks', 'run', 'etl_pipeline_dag', 'load_to_final_data', 'manual__2024-06-23T02:38:51.935536+00:00', '--job-id', '78', '--raw', '--subdir', 'DAGS_FOLDER/bigquery.py', '--cfg-path', '/tmp/tmp6o9_udrt']
[2024-06-23T02:39:36.272+0000] {standard_task_runner.py:91} INFO - Job 78: Subtask load_to_final_data
[2024-06-23T02:39:36.326+0000] {task_command.py:426} INFO - Running <TaskInstance: etl_pipeline_dag.load_to_final_data manual__2024-06-23T02:38:51.935536+00:00 [running]> on host 64917a389d59
[2024-06-23T02:39:36.440+0000] {taskinstance.py:2648} INFO - Exporting env vars: AIRFLOW_CTX_DAG_OWNER='***' AIRFLOW_CTX_DAG_ID='etl_pipeline_dag' AIRFLOW_CTX_TASK_ID='load_to_final_data' AIRFLOW_CTX_EXECUTION_DATE='2024-06-23T02:38:51.935536+00:00' AIRFLOW_CTX_TRY_NUMBER='1' AIRFLOW_CTX_DAG_RUN_ID='manual__2024-06-23T02:38:51.935536+00:00'
[2024-06-23T02:39:36.442+0000] {taskinstance.py:430} INFO - ::endgroup::
[2024-06-23T02:39:36.469+0000] {connection.py:274} WARNING - Connection schemes (type: google_cloud_platform) shall not contain '_' according to RFC3986.
[2024-06-23T02:39:36.472+0000] {base.py:84} INFO - Using connection ID 'google_cloud_default' for task execution.
[2024-06-23T02:39:36.528+0000] {bigquery.py:2872} INFO - Executing: {'query': {'query': '\n                    INSERT INTO `boreal-forest-427103-q9.final_data.new-data` (id, gender, bike, swim, run, other, 1s_critical_power)\n                    SELECT \n                        id,\n                        gender,\n                        bike,\n                        swim,\n                        run,\n                        other,\n                        NULL as 1s_critical_power\n                    FROM \n                        `transformed_1.final_test`\n                ', 'useLegacySql': False}}'
[2024-06-23T02:39:36.529+0000] {bigquery.py:1670} INFO - Inserting job ***_etl_pipeline_dag_load_to_final_data_2024_06_23T02_38_51_935536_00_00_66f90e4e3f87b898429b689798f355e7
[2024-06-23T02:39:37.514+0000] {taskinstance.py:441} INFO - ::group::Post task execution logs
[2024-06-23T02:39:37.515+0000] {taskinstance.py:2905} ERROR - Task failed with exception
Traceback (most recent call last):
  File "/home/airflow/.local/lib/python3.12/site-packages/airflow/models/taskinstance.py", line 465, in _execute_task
    result = _execute_callable(context=context, **execute_callable_kwargs)
             ^^^^^^^^^^^^^^^^^^^^^^^^^^^^^^^^^^^^^^^^^^^^^^^^^^^^^^^^^^^^^
  File "/home/airflow/.local/lib/python3.12/site-packages/airflow/models/taskinstance.py", line 432, in _execute_callable
    return execute_callable(context=context, **execute_callable_kwargs)
           ^^^^^^^^^^^^^^^^^^^^^^^^^^^^^^^^^^^^^^^^^^^^^^^^^^^^^^^^^^^^
  File "/home/airflow/.local/lib/python3.12/site-packages/airflow/models/baseoperator.py", line 401, in wrapper
    return func(self, *args, **kwargs)
           ^^^^^^^^^^^^^^^^^^^^^^^^^^^
  File "/home/airflow/.local/lib/python3.12/site-packages/airflow/providers/google/cloud/operators/bigquery.py", line 2931, in execute
    job.result(timeout=self.result_timeout, retry=self.result_retry)
  File "/home/airflow/.local/lib/python3.12/site-packages/google/cloud/bigquery/job/query.py", line 1590, in result
    do_get_result()
  File "/home/airflow/.local/lib/python3.12/site-packages/google/cloud/bigquery/job/query.py", line 1579, in do_get_result
    super(QueryJob, self).result(retry=retry, timeout=timeout)
  File "/home/airflow/.local/lib/python3.12/site-packages/google/cloud/bigquery/job/base.py", line 971, in result
    return super(_AsyncJob, self).result(timeout=timeout, **kwargs)
           ^^^^^^^^^^^^^^^^^^^^^^^^^^^^^^^^^^^^^^^^^^^^^^^^^^^^^^^^
  File "/home/airflow/.local/lib/python3.12/site-packages/google/api_core/future/polling.py", line 261, in result
    raise self._exception
google.api_core.exceptions.BadRequest: 400 Syntax error: Unexpected "1s_critical_power" at [2:116]; reason: invalidQuery, location: query, message: Syntax error: Unexpected "1s_critical_power" at [2:116]

Location: US
Job ID: airflow_etl_pipeline_dag_load_to_final_data_2024_06_23T02_38_51_935536_00_00_66f90e4e3f87b898429b689798f355e7

[2024-06-23T02:39:37.538+0000] {taskinstance.py:1206} INFO - Marking task as FAILED. dag_id=etl_pipeline_dag, task_id=load_to_final_data, run_id=manual__2024-06-23T02:38:51.935536+00:00, execution_date=20240623T023851, start_date=20240623T023936, end_date=20240623T023937
[2024-06-23T02:39:37.564+0000] {standard_task_runner.py:110} ERROR - Failed to execute job 78 for task load_to_final_data (400 Syntax error: Unexpected "1s_critical_power" at [2:116]; reason: invalidQuery, location: query, message: Syntax error: Unexpected "1s_critical_power" at [2:116]

Location: US
Job ID: airflow_etl_pipeline_dag_load_to_final_data_2024_06_23T02_38_51_935536_00_00_66f90e4e3f87b898429b689798f355e7
; 4644)
[2024-06-23T02:39:37.609+0000] {local_task_job_runner.py:240} INFO - Task exited with return code 1
[2024-06-23T02:39:37.651+0000] {taskinstance.py:3503} INFO - 0 downstream tasks scheduled from follow-on schedule check
[2024-06-23T02:39:37.656+0000] {local_task_job_runner.py:222} INFO - ::endgroup::
