[2024-06-22T07:30:33.137+0000] {local_task_job_runner.py:120} INFO - ::group::Pre task execution logs
[2024-06-22T07:30:33.174+0000] {taskinstance.py:2076} INFO - Dependencies all met for dep_context=non-requeueable deps ti=<TaskInstance: gcs_processing.etl_process manual__2024-06-22T07:24:44.878729+00:00 [queued]>
[2024-06-22T07:30:33.190+0000] {taskinstance.py:2076} INFO - Dependencies all met for dep_context=requeueable deps ti=<TaskInstance: gcs_processing.etl_process manual__2024-06-22T07:24:44.878729+00:00 [queued]>
[2024-06-22T07:30:33.192+0000] {taskinstance.py:2306} INFO - Starting attempt 2 of 2
[2024-06-22T07:30:33.218+0000] {taskinstance.py:2330} INFO - Executing <Task(PythonOperator): etl_process> on 2024-06-22 07:24:44.878729+00:00
[2024-06-22T07:30:33.230+0000] {warnings.py:112} WARNING - /home/***/.local/lib/python3.12/site-packages/***/task/task_runner/standard_task_runner.py:61: DeprecationWarning: This process (pid=471) is multi-threaded, use of fork() may lead to deadlocks in the child.
  pid = os.fork()

[2024-06-22T07:30:33.233+0000] {standard_task_runner.py:63} INFO - Started process 472 to run task
[2024-06-22T07:30:33.232+0000] {standard_task_runner.py:90} INFO - Running: ['***', 'tasks', 'run', 'gcs_processing', 'etl_process', 'manual__2024-06-22T07:24:44.878729+00:00', '--job-id', '22', '--raw', '--subdir', 'DAGS_FOLDER/gcs_processing.py', '--cfg-path', '/tmp/tmp3ziav4pk']
[2024-06-22T07:30:33.236+0000] {standard_task_runner.py:91} INFO - Job 22: Subtask etl_process
[2024-06-22T07:30:33.336+0000] {task_command.py:426} INFO - Running <TaskInstance: gcs_processing.etl_process manual__2024-06-22T07:24:44.878729+00:00 [running]> on host 03e9b5f54aa2
[2024-06-22T07:30:33.551+0000] {taskinstance.py:2648} INFO - Exporting env vars: AIRFLOW_CTX_DAG_OWNER='***' AIRFLOW_CTX_DAG_ID='gcs_processing' AIRFLOW_CTX_TASK_ID='etl_process' AIRFLOW_CTX_EXECUTION_DATE='2024-06-22T07:24:44.878729+00:00' AIRFLOW_CTX_TRY_NUMBER='2' AIRFLOW_CTX_DAG_RUN_ID='manual__2024-06-22T07:24:44.878729+00:00'
[2024-06-22T07:30:33.555+0000] {taskinstance.py:430} INFO - ::endgroup::
[2024-06-22T07:30:33.618+0000] {connection.py:274} WARNING - Connection schemes (type: google_cloud_platform) shall not contain '_' according to RFC3986.
[2024-06-22T07:30:33.621+0000] {base.py:84} INFO - Using connection ID 'google_cloud_default' for task execution.
[2024-06-22T07:30:35.439+0000] {gcs.py:354} ERROR - Download attempt of object: golden-cheetah-datasets/datasets/athletes.csv from golden-cheetah-datasets has failed. Attempt: 0, max 1.
[2024-06-22T07:30:35.441+0000] {taskinstance.py:441} INFO - ::group::Post task execution logs
[2024-06-22T07:30:35.443+0000] {taskinstance.py:2905} ERROR - Task failed with exception
Traceback (most recent call last):
  File "/home/airflow/.local/lib/python3.12/site-packages/google/cloud/storage/blob.py", line 4362, in _prep_and_do_download
    self._do_download(
  File "/home/airflow/.local/lib/python3.12/site-packages/google/cloud/storage/blob.py", line 1017, in _do_download
    response = download.consume(transport, timeout=timeout)
               ^^^^^^^^^^^^^^^^^^^^^^^^^^^^^^^^^^^^^^^^^^^^
  File "/home/airflow/.local/lib/python3.12/site-packages/google/resumable_media/requests/download.py", line 237, in consume
    return _request_helpers.wait_and_retry(
           ^^^^^^^^^^^^^^^^^^^^^^^^^^^^^^^^
  File "/home/airflow/.local/lib/python3.12/site-packages/google/resumable_media/requests/_request_helpers.py", line 155, in wait_and_retry
    response = func()
               ^^^^^^
  File "/home/airflow/.local/lib/python3.12/site-packages/google/resumable_media/requests/download.py", line 219, in retriable_request
    self._process_response(result)
  File "/home/airflow/.local/lib/python3.12/site-packages/google/resumable_media/_download.py", line 188, in _process_response
    _helpers.require_status_code(
  File "/home/airflow/.local/lib/python3.12/site-packages/google/resumable_media/_helpers.py", line 108, in require_status_code
    raise common.InvalidResponse(
google.resumable_media.common.InvalidResponse: ('Request failed with status code', 404, 'Expected one of', 200, 206)

During handling of the above exception, another exception occurred:

Traceback (most recent call last):
  File "/home/airflow/.local/lib/python3.12/site-packages/airflow/models/taskinstance.py", line 465, in _execute_task
    result = _execute_callable(context=context, **execute_callable_kwargs)
             ^^^^^^^^^^^^^^^^^^^^^^^^^^^^^^^^^^^^^^^^^^^^^^^^^^^^^^^^^^^^^
  File "/home/airflow/.local/lib/python3.12/site-packages/airflow/models/taskinstance.py", line 432, in _execute_callable
    return execute_callable(context=context, **execute_callable_kwargs)
           ^^^^^^^^^^^^^^^^^^^^^^^^^^^^^^^^^^^^^^^^^^^^^^^^^^^^^^^^^^^^
  File "/home/airflow/.local/lib/python3.12/site-packages/airflow/models/baseoperator.py", line 401, in wrapper
    return func(self, *args, **kwargs)
           ^^^^^^^^^^^^^^^^^^^^^^^^^^^
  File "/home/airflow/.local/lib/python3.12/site-packages/airflow/operators/python.py", line 235, in execute
    return_value = self.execute_callable()
                   ^^^^^^^^^^^^^^^^^^^^^^^
  File "/home/airflow/.local/lib/python3.12/site-packages/airflow/operators/python.py", line 252, in execute_callable
    return self.python_callable(*self.op_args, **self.op_kwargs)
           ^^^^^^^^^^^^^^^^^^^^^^^^^^^^^^^^^^^^^^^^^^^^^^^^^^^^^
  File "/opt/airflow/dags/gcs_processing.py", line 15, in etl_process
    source_data = gcs_hook.download(bucket_name, source_blob)
                  ^^^^^^^^^^^^^^^^^^^^^^^^^^^^^^^^^^^^^^^^^^^
  File "/home/airflow/.local/lib/python3.12/site-packages/airflow/providers/google/cloud/hooks/gcs.py", line 350, in download
    return blob.download_as_bytes()
           ^^^^^^^^^^^^^^^^^^^^^^^^
  File "/home/airflow/.local/lib/python3.12/site-packages/google/cloud/storage/blob.py", line 1435, in download_as_bytes
    self._prep_and_do_download(
  File "/home/airflow/.local/lib/python3.12/site-packages/google/cloud/storage/blob.py", line 4375, in _prep_and_do_download
    _raise_from_invalid_response(exc)
  File "/home/airflow/.local/lib/python3.12/site-packages/google/cloud/storage/blob.py", line 4847, in _raise_from_invalid_response
    raise exceptions.from_http_status(response.status_code, message, response=response)
google.api_core.exceptions.NotFound: 404 GET https://storage.googleapis.com/download/storage/v1/b/golden-cheetah-datasets/o/golden-cheetah-datasets%2Fdatasets%2Fathletes.csv?alt=media: No such object: golden-cheetah-datasets/golden-cheetah-datasets/datasets/athletes.csv: ('Request failed with status code', 404, 'Expected one of', <HTTPStatus.OK: 200>, <HTTPStatus.PARTIAL_CONTENT: 206>)
[2024-06-22T07:30:35.533+0000] {taskinstance.py:1206} INFO - Marking task as FAILED. dag_id=gcs_processing, task_id=etl_process, run_id=manual__2024-06-22T07:24:44.878729+00:00, execution_date=20240622T072444, start_date=20240622T073033, end_date=20240622T073035
[2024-06-22T07:30:35.558+0000] {standard_task_runner.py:110} ERROR - Failed to execute job 22 for task etl_process (404 GET https://storage.googleapis.com/download/storage/v1/b/golden-cheetah-datasets/o/golden-cheetah-datasets%2Fdatasets%2Fathletes.csv?alt=media: No such object: golden-cheetah-datasets/golden-cheetah-datasets/datasets/athletes.csv: ('Request failed with status code', 404, 'Expected one of', <HTTPStatus.OK: 200>, <HTTPStatus.PARTIAL_CONTENT: 206>); 472)
[2024-06-22T07:30:35.584+0000] {local_task_job_runner.py:240} INFO - Task exited with return code 1
[2024-06-22T07:30:35.612+0000] {taskinstance.py:3503} INFO - 0 downstream tasks scheduled from follow-on schedule check
[2024-06-22T07:30:35.617+0000] {local_task_job_runner.py:222} INFO - ::endgroup::
