[2024-06-22T06:10:55.432+0000] {local_task_job_runner.py:120} INFO - ::group::Pre task execution logs
[2024-06-22T06:10:55.450+0000] {taskinstance.py:2076} INFO - Dependencies all met for dep_context=non-requeueable deps ti=<TaskInstance: gcs_processing.etl_process scheduled__2024-06-21T00:00:00+00:00 [queued]>
[2024-06-22T06:10:55.460+0000] {taskinstance.py:2076} INFO - Dependencies all met for dep_context=requeueable deps ti=<TaskInstance: gcs_processing.etl_process scheduled__2024-06-21T00:00:00+00:00 [queued]>
[2024-06-22T06:10:55.461+0000] {taskinstance.py:2306} INFO - Starting attempt 2 of 2
[2024-06-22T06:10:55.475+0000] {taskinstance.py:2330} INFO - Executing <Task(PythonOperator): etl_process> on 2024-06-21 00:00:00+00:00
[2024-06-22T06:10:55.484+0000] {warnings.py:112} WARNING - /home/***/.local/lib/python3.12/site-packages/***/task/task_runner/standard_task_runner.py:61: DeprecationWarning: This process (pid=1587) is multi-threaded, use of fork() may lead to deadlocks in the child.
  pid = os.fork()

[2024-06-22T06:10:55.486+0000] {standard_task_runner.py:63} INFO - Started process 1588 to run task
[2024-06-22T06:10:55.485+0000] {standard_task_runner.py:90} INFO - Running: ['***', 'tasks', 'run', 'gcs_processing', 'etl_process', 'scheduled__2024-06-21T00:00:00+00:00', '--job-id', '6', '--raw', '--subdir', 'DAGS_FOLDER/gcs_processing.py', '--cfg-path', '/tmp/tmpvdgzq8ob']
[2024-06-22T06:10:55.488+0000] {standard_task_runner.py:91} INFO - Job 6: Subtask etl_process
[2024-06-22T06:10:55.542+0000] {task_command.py:426} INFO - Running <TaskInstance: gcs_processing.etl_process scheduled__2024-06-21T00:00:00+00:00 [running]> on host ef7fea064a97
[2024-06-22T06:10:55.643+0000] {taskinstance.py:2648} INFO - Exporting env vars: AIRFLOW_CTX_DAG_OWNER='***' AIRFLOW_CTX_DAG_ID='gcs_processing' AIRFLOW_CTX_TASK_ID='etl_process' AIRFLOW_CTX_EXECUTION_DATE='2024-06-21T00:00:00+00:00' AIRFLOW_CTX_TRY_NUMBER='2' AIRFLOW_CTX_DAG_RUN_ID='scheduled__2024-06-21T00:00:00+00:00'
[2024-06-22T06:10:55.644+0000] {taskinstance.py:430} INFO - ::endgroup::
[2024-06-22T06:10:55.683+0000] {connection.py:274} WARNING - Connection schemes (type: google_cloud_platform) shall not contain '_' according to RFC3986.
[2024-06-22T06:10:55.686+0000] {base.py:84} INFO - Using connection ID 'google_cloud_default' for task execution.
[2024-06-22T06:10:55.688+0000] {taskinstance.py:441} INFO - ::group::Post task execution logs
[2024-06-22T06:10:55.689+0000] {taskinstance.py:2905} ERROR - Task failed with exception
Traceback (most recent call last):
  File "/home/airflow/.local/lib/python3.12/site-packages/airflow/models/taskinstance.py", line 465, in _execute_task
    result = _execute_callable(context=context, **execute_callable_kwargs)
             ^^^^^^^^^^^^^^^^^^^^^^^^^^^^^^^^^^^^^^^^^^^^^^^^^^^^^^^^^^^^^
  File "/home/airflow/.local/lib/python3.12/site-packages/airflow/models/taskinstance.py", line 432, in _execute_callable
    return execute_callable(context=context, **execute_callable_kwargs)
           ^^^^^^^^^^^^^^^^^^^^^^^^^^^^^^^^^^^^^^^^^^^^^^^^^^^^^^^^^^^^
  File "/home/airflow/.local/lib/python3.12/site-packages/airflow/models/baseoperator.py", line 401, in wrapper
    return func(self, *args, **kwargs)
           ^^^^^^^^^^^^^^^^^^^^^^^^^^^
  File "/home/airflow/.local/lib/python3.12/site-packages/airflow/operators/python.py", line 235, in execute
    return_value = self.execute_callable()
                   ^^^^^^^^^^^^^^^^^^^^^^^
  File "/home/airflow/.local/lib/python3.12/site-packages/airflow/operators/python.py", line 252, in execute_callable
    return self.python_callable(*self.op_args, **self.op_kwargs)
           ^^^^^^^^^^^^^^^^^^^^^^^^^^^^^^^^^^^^^^^^^^^^^^^^^^^^^
  File "/opt/airflow/dags/gcs_processing.py", line 11, in etl_process
    source_data = gcs_hook.download(bucket_name, source_blob)
                  ^^^^^^^^^^^^^^^^^^^^^^^^^^^^^^^^^^^^^^^^^^^
  File "/home/airflow/.local/lib/python3.12/site-packages/airflow/providers/google/cloud/hooks/gcs.py", line 341, in download
    client = self.get_conn()
             ^^^^^^^^^^^^^^^
  File "/home/airflow/.local/lib/python3.12/site-packages/airflow/providers/google/cloud/hooks/gcs.py", line 173, in get_conn
    credentials=self.get_credentials(), client_info=CLIENT_INFO, project=self.project_id
                ^^^^^^^^^^^^^^^^^^^^^^
  File "/home/airflow/.local/lib/python3.12/site-packages/airflow/providers/google/common/hooks/base_google.py", line 332, in get_credentials
    credentials, _ = self.get_credentials_and_project_id()
                     ^^^^^^^^^^^^^^^^^^^^^^^^^^^^^^^^^^^^^
  File "/home/airflow/.local/lib/python3.12/site-packages/airflow/providers/google/common/hooks/base_google.py", line 308, in get_credentials_and_project_id
    credentials, project_id = get_credentials_and_project_id(
                              ^^^^^^^^^^^^^^^^^^^^^^^^^^^^^^^
  File "/home/airflow/.local/lib/python3.12/site-packages/airflow/providers/google/cloud/utils/credentials_provider.py", line 371, in get_credentials_and_project_id
    return _CredentialProvider(*args, **kwargs).get_credentials_and_project()
           ^^^^^^^^^^^^^^^^^^^^^^^^^^^^^^^^^^^^^^^^^^^^^^^^^^^^^^^^^^^^^^^^^^
  File "/home/airflow/.local/lib/python3.12/site-packages/airflow/providers/google/cloud/utils/credentials_provider.py", line 245, in get_credentials_and_project
    credentials, project_id = self._get_credentials_using_key_path()
                              ^^^^^^^^^^^^^^^^^^^^^^^^^^^^^^^^^^^^^^
  File "/home/airflow/.local/lib/python3.12/site-packages/airflow/providers/google/cloud/utils/credentials_provider.py", line 295, in _get_credentials_using_key_path
    credentials = google.oauth2.service_account.Credentials.from_service_account_file(
                  ^^^^^^^^^^^^^^^^^^^^^^^^^^^^^^^^^^^^^^^^^^^^^^^^^^^^^^^^^^^^^^^^^^^^
  File "/home/airflow/.local/lib/python3.12/site-packages/google/oauth2/service_account.py", line 258, in from_service_account_file
    info, signer = _service_account_info.from_filename(
                   ^^^^^^^^^^^^^^^^^^^^^^^^^^^^^^^^^^^^
  File "/home/airflow/.local/lib/python3.12/site-packages/google/auth/_service_account_info.py", line 78, in from_filename
    with io.open(filename, "r", encoding="utf-8") as json_file:
         ^^^^^^^^^^^^^^^^^^^^^^^^^^^^^^^^^^^^^^^^
FileNotFoundError: [Errno 2] No such file or directory: 'C:\\Users\\Yerko\\Desktop\\Security Topics\\Airflow\\dags\\keys\\boreal-forest-427103-q9-fc0cdec7fd29.json'
[2024-06-22T06:10:55.716+0000] {taskinstance.py:1206} INFO - Marking task as FAILED. dag_id=gcs_processing, task_id=etl_process, run_id=scheduled__2024-06-21T00:00:00+00:00, execution_date=20240621T000000, start_date=20240622T061055, end_date=20240622T061055
[2024-06-22T06:10:55.737+0000] {standard_task_runner.py:110} ERROR - Failed to execute job 6 for task etl_process ([Errno 2] No such file or directory: 'C:\\Users\\Yerko\\Desktop\\Security Topics\\Airflow\\dags\\keys\\boreal-forest-427103-q9-fc0cdec7fd29.json'; 1588)
[2024-06-22T06:10:55.781+0000] {local_task_job_runner.py:240} INFO - Task exited with return code 1
[2024-06-22T06:10:55.804+0000] {taskinstance.py:3503} INFO - 0 downstream tasks scheduled from follow-on schedule check
[2024-06-22T06:10:55.808+0000] {local_task_job_runner.py:222} INFO - ::endgroup::
[2024-06-22T06:36:47.664+0000] {local_task_job_runner.py:120} INFO - ::group::Pre task execution logs
[2024-06-22T06:36:47.697+0000] {taskinstance.py:2076} INFO - Dependencies all met for dep_context=non-requeueable deps ti=<TaskInstance: gcs_processing.etl_process scheduled__2024-06-21T00:00:00+00:00 [queued]>
[2024-06-22T06:36:47.717+0000] {taskinstance.py:2076} INFO - Dependencies all met for dep_context=requeueable deps ti=<TaskInstance: gcs_processing.etl_process scheduled__2024-06-21T00:00:00+00:00 [queued]>
[2024-06-22T06:36:47.718+0000] {taskinstance.py:2306} INFO - Starting attempt 2 of 2
[2024-06-22T06:36:47.744+0000] {taskinstance.py:2330} INFO - Executing <Task(PythonOperator): etl_process> on 2024-06-21 00:00:00+00:00
[2024-06-22T06:36:47.769+0000] {warnings.py:112} WARNING - /home/***/.local/lib/python3.12/site-packages/***/task/task_runner/standard_task_runner.py:61: DeprecationWarning: This process (pid=1905) is multi-threaded, use of fork() may lead to deadlocks in the child.
  pid = os.fork()

[2024-06-22T06:36:47.774+0000] {standard_task_runner.py:63} INFO - Started process 1907 to run task
[2024-06-22T06:36:47.772+0000] {standard_task_runner.py:90} INFO - Running: ['***', 'tasks', 'run', 'gcs_processing', 'etl_process', 'scheduled__2024-06-21T00:00:00+00:00', '--job-id', '13', '--raw', '--subdir', 'DAGS_FOLDER/gcs_processing.py', '--cfg-path', '/tmp/tmpjlyclkvg']
[2024-06-22T06:36:47.779+0000] {standard_task_runner.py:91} INFO - Job 13: Subtask etl_process
[2024-06-22T06:36:47.901+0000] {task_command.py:426} INFO - Running <TaskInstance: gcs_processing.etl_process scheduled__2024-06-21T00:00:00+00:00 [running]> on host ef7fea064a97
[2024-06-22T06:36:48.035+0000] {taskinstance.py:2648} INFO - Exporting env vars: AIRFLOW_CTX_DAG_OWNER='***' AIRFLOW_CTX_DAG_ID='gcs_processing' AIRFLOW_CTX_TASK_ID='etl_process' AIRFLOW_CTX_EXECUTION_DATE='2024-06-21T00:00:00+00:00' AIRFLOW_CTX_TRY_NUMBER='2' AIRFLOW_CTX_DAG_RUN_ID='scheduled__2024-06-21T00:00:00+00:00'
[2024-06-22T06:36:48.038+0000] {taskinstance.py:430} INFO - ::endgroup::
[2024-06-22T06:36:48.101+0000] {taskinstance.py:441} INFO - ::group::Post task execution logs
[2024-06-22T06:36:48.117+0000] {taskinstance.py:2905} ERROR - Task failed with exception
Traceback (most recent call last):
  File "/home/airflow/.local/lib/python3.12/site-packages/airflow/models/taskinstance.py", line 465, in _execute_task
    result = _execute_callable(context=context, **execute_callable_kwargs)
             ^^^^^^^^^^^^^^^^^^^^^^^^^^^^^^^^^^^^^^^^^^^^^^^^^^^^^^^^^^^^^
  File "/home/airflow/.local/lib/python3.12/site-packages/airflow/models/taskinstance.py", line 432, in _execute_callable
    return execute_callable(context=context, **execute_callable_kwargs)
           ^^^^^^^^^^^^^^^^^^^^^^^^^^^^^^^^^^^^^^^^^^^^^^^^^^^^^^^^^^^^
  File "/home/airflow/.local/lib/python3.12/site-packages/airflow/models/baseoperator.py", line 401, in wrapper
    return func(self, *args, **kwargs)
           ^^^^^^^^^^^^^^^^^^^^^^^^^^^
  File "/home/airflow/.local/lib/python3.12/site-packages/airflow/operators/python.py", line 235, in execute
    return_value = self.execute_callable()
                   ^^^^^^^^^^^^^^^^^^^^^^^
  File "/home/airflow/.local/lib/python3.12/site-packages/airflow/operators/python.py", line 252, in execute_callable
    return self.python_callable(*self.op_args, **self.op_kwargs)
           ^^^^^^^^^^^^^^^^^^^^^^^^^^^^^^^^^^^^^^^^^^^^^^^^^^^^^
  File "/opt/airflow/dags/gcs_processing.py", line 12, in etl_process
    gcs_hook = GCSHook(gcp_conn_id='google_cloud_default', key_path=key_path)
               ^^^^^^^^^^^^^^^^^^^^^^^^^^^^^^^^^^^^^^^^^^^^^^^^^^^^^^^^^^^^^^
  File "/home/airflow/.local/lib/python3.12/site-packages/airflow/providers/google/cloud/hooks/gcs.py", line 164, in __init__
    super().__init__(
  File "/home/airflow/.local/lib/python3.12/site-packages/airflow/providers/google/common/hooks/base_google.py", line 274, in __init__
    self.extras: dict = self.get_connection(self.gcp_conn_id).extra_dejson
                        ^^^^^^^^^^^^^^^^^^^^^^^^^^^^^^^^^^^^^
  File "/home/airflow/.local/lib/python3.12/site-packages/airflow/hooks/base.py", line 83, in get_connection
    conn = Connection.get_connection_from_secrets(conn_id)
           ^^^^^^^^^^^^^^^^^^^^^^^^^^^^^^^^^^^^^^^^^^^^^^^
  File "/home/airflow/.local/lib/python3.12/site-packages/airflow/models/connection.py", line 519, in get_connection_from_secrets
    raise AirflowNotFoundException(f"The conn_id `{conn_id}` isn't defined")
airflow.exceptions.AirflowNotFoundException: The conn_id `google_cloud_default` isn't defined
[2024-06-22T06:36:48.132+0000] {taskinstance.py:1206} INFO - Marking task as FAILED. dag_id=gcs_processing, task_id=etl_process, run_id=scheduled__2024-06-21T00:00:00+00:00, execution_date=20240621T000000, start_date=20240622T063647, end_date=20240622T063648
[2024-06-22T06:36:48.159+0000] {standard_task_runner.py:110} ERROR - Failed to execute job 13 for task etl_process (The conn_id `google_cloud_default` isn't defined; 1907)
[2024-06-22T06:36:48.192+0000] {local_task_job_runner.py:240} INFO - Task exited with return code 1
[2024-06-22T06:36:48.211+0000] {local_task_job_runner.py:222} INFO - ::endgroup::
