[2024-06-23T03:34:38.791+0000] {local_task_job_runner.py:120} INFO - ::group::Pre task execution logs
[2024-06-23T03:34:38.812+0000] {taskinstance.py:2076} INFO - Dependencies all met for dep_context=non-requeueable deps ti=<TaskInstance: etl_pipeline_dag_secure.extract_data_from_bigquery scheduled__2024-06-22T00:00:00+00:00 [queued]>
[2024-06-23T03:34:38.822+0000] {taskinstance.py:2076} INFO - Dependencies all met for dep_context=requeueable deps ti=<TaskInstance: etl_pipeline_dag_secure.extract_data_from_bigquery scheduled__2024-06-22T00:00:00+00:00 [queued]>
[2024-06-23T03:34:38.823+0000] {taskinstance.py:2306} INFO - Starting attempt 2 of 4
[2024-06-23T03:34:38.843+0000] {taskinstance.py:2330} INFO - Executing <Task(PythonOperator): extract_data_from_bigquery> on 2024-06-22 00:00:00+00:00
[2024-06-23T03:34:38.868+0000] {standard_task_runner.py:90} INFO - Running: ['***', 'tasks', 'run', 'etl_pipeline_dag_secure', 'extract_data_from_bigquery', 'scheduled__2024-06-22T00:00:00+00:00', '--job-id', '97', '--raw', '--subdir', 'DAGS_FOLDER/bigquery.py', '--cfg-path', '/tmp/tmpdtse7jt6']
[2024-06-23T03:34:38.866+0000] {warnings.py:112} WARNING - /home/***/.local/lib/python3.12/site-packages/***/task/task_runner/standard_task_runner.py:61: DeprecationWarning: This process (pid=5344) is multi-threaded, use of fork() may lead to deadlocks in the child.
  pid = os.fork()

[2024-06-23T03:34:38.871+0000] {standard_task_runner.py:91} INFO - Job 97: Subtask extract_data_from_bigquery
[2024-06-23T03:34:38.872+0000] {standard_task_runner.py:63} INFO - Started process 5349 to run task
[2024-06-23T03:34:39.010+0000] {task_command.py:426} INFO - Running <TaskInstance: etl_pipeline_dag_secure.extract_data_from_bigquery scheduled__2024-06-22T00:00:00+00:00 [running]> on host 64917a389d59
[2024-06-23T03:34:39.148+0000] {taskinstance.py:2648} INFO - Exporting env vars: AIRFLOW_CTX_DAG_OWNER='***' AIRFLOW_CTX_DAG_ID='etl_pipeline_dag_secure' AIRFLOW_CTX_TASK_ID='extract_data_from_bigquery' AIRFLOW_CTX_EXECUTION_DATE='2024-06-22T00:00:00+00:00' AIRFLOW_CTX_TRY_NUMBER='2' AIRFLOW_CTX_DAG_RUN_ID='scheduled__2024-06-22T00:00:00+00:00'
[2024-06-23T03:34:39.157+0000] {taskinstance.py:430} INFO - ::endgroup::
[2024-06-23T03:34:39.231+0000] {_metadata.py:139} WARNING - Compute Engine Metadata server unavailable on attempt 1 of 3. Reason: [Errno 111] Connection refused
[2024-06-23T03:34:39.234+0000] {_metadata.py:139} WARNING - Compute Engine Metadata server unavailable on attempt 2 of 3. Reason: [Errno 111] Connection refused
[2024-06-23T03:34:39.237+0000] {_metadata.py:139} WARNING - Compute Engine Metadata server unavailable on attempt 3 of 3. Reason: [Errno 111] Connection refused
[2024-06-23T03:34:39.240+0000] {_default.py:338} WARNING - Authentication failed using Compute Engine authentication due to unavailable metadata server.
[2024-06-23T03:34:39.240+0000] {taskinstance.py:441} INFO - ::group::Post task execution logs
[2024-06-23T03:34:39.242+0000] {taskinstance.py:2905} ERROR - Task failed with exception
Traceback (most recent call last):
  File "/home/airflow/.local/lib/python3.12/site-packages/airflow/models/taskinstance.py", line 465, in _execute_task
    result = _execute_callable(context=context, **execute_callable_kwargs)
             ^^^^^^^^^^^^^^^^^^^^^^^^^^^^^^^^^^^^^^^^^^^^^^^^^^^^^^^^^^^^^
  File "/home/airflow/.local/lib/python3.12/site-packages/airflow/models/taskinstance.py", line 432, in _execute_callable
    return execute_callable(context=context, **execute_callable_kwargs)
           ^^^^^^^^^^^^^^^^^^^^^^^^^^^^^^^^^^^^^^^^^^^^^^^^^^^^^^^^^^^^
  File "/home/airflow/.local/lib/python3.12/site-packages/airflow/models/baseoperator.py", line 401, in wrapper
    return func(self, *args, **kwargs)
           ^^^^^^^^^^^^^^^^^^^^^^^^^^^
  File "/home/airflow/.local/lib/python3.12/site-packages/airflow/operators/python.py", line 235, in execute
    return_value = self.execute_callable()
                   ^^^^^^^^^^^^^^^^^^^^^^^
  File "/home/airflow/.local/lib/python3.12/site-packages/airflow/operators/python.py", line 252, in execute_callable
    return self.python_callable(*self.op_args, **self.op_kwargs)
           ^^^^^^^^^^^^^^^^^^^^^^^^^^^^^^^^^^^^^^^^^^^^^^^^^^^^^
  File "/opt/airflow/dags/bigquery.py", line 22, in extract_data_from_bigquery
    client = bigquery.Client()
             ^^^^^^^^^^^^^^^^^
  File "/home/airflow/.local/lib/python3.12/site-packages/google/cloud/bigquery/client.py", line 241, in __init__
    super(Client, self).__init__(
  File "/home/airflow/.local/lib/python3.12/site-packages/google/cloud/client/__init__.py", line 320, in __init__
    _ClientProjectMixin.__init__(self, project=project, credentials=credentials)
  File "/home/airflow/.local/lib/python3.12/site-packages/google/cloud/client/__init__.py", line 268, in __init__
    project = self._determine_default(project)
              ^^^^^^^^^^^^^^^^^^^^^^^^^^^^^^^^
  File "/home/airflow/.local/lib/python3.12/site-packages/google/cloud/client/__init__.py", line 287, in _determine_default
    return _determine_default_project(project)
           ^^^^^^^^^^^^^^^^^^^^^^^^^^^^^^^^^^^
  File "/home/airflow/.local/lib/python3.12/site-packages/google/cloud/_helpers/__init__.py", line 152, in _determine_default_project
    _, project = google.auth.default()
                 ^^^^^^^^^^^^^^^^^^^^^
  File "/home/airflow/.local/lib/python3.12/site-packages/google/auth/_default.py", line 691, in default
    raise exceptions.DefaultCredentialsError(_CLOUD_SDK_MISSING_CREDENTIALS)
google.auth.exceptions.DefaultCredentialsError: Your default credentials were not found. To set up Application Default Credentials, see https://cloud.google.com/docs/authentication/external/set-up-adc for more information.
[2024-06-23T03:34:39.274+0000] {taskinstance.py:1206} INFO - Marking task as UP_FOR_RETRY. dag_id=etl_pipeline_dag_secure, task_id=extract_data_from_bigquery, run_id=scheduled__2024-06-22T00:00:00+00:00, execution_date=20240622T000000, start_date=20240623T033438, end_date=20240623T033439
[2024-06-23T03:34:39.295+0000] {standard_task_runner.py:110} ERROR - Failed to execute job 97 for task extract_data_from_bigquery (Your default credentials were not found. To set up Application Default Credentials, see https://cloud.google.com/docs/authentication/external/set-up-adc for more information.; 5349)
[2024-06-23T03:34:39.329+0000] {local_task_job_runner.py:240} INFO - Task exited with return code 1
[2024-06-23T03:34:39.353+0000] {taskinstance.py:3503} INFO - 0 downstream tasks scheduled from follow-on schedule check
[2024-06-23T03:34:39.356+0000] {local_task_job_runner.py:222} INFO - ::endgroup::
