[2024-06-22T21:58:06.700+0000] {local_task_job_runner.py:120} INFO - ::group::Pre task execution logs
[2024-06-22T21:58:06.722+0000] {taskinstance.py:2076} INFO - Dependencies all met for dep_context=non-requeueable deps ti=<TaskInstance: transform_data_dag.get_data manual__2024-06-22T21:57:35.049966+00:00 [queued]>
[2024-06-22T21:58:06.736+0000] {taskinstance.py:2076} INFO - Dependencies all met for dep_context=requeueable deps ti=<TaskInstance: transform_data_dag.get_data manual__2024-06-22T21:57:35.049966+00:00 [queued]>
[2024-06-22T21:58:06.736+0000] {taskinstance.py:2306} INFO - Starting attempt 1 of 1
[2024-06-22T21:58:06.762+0000] {taskinstance.py:2330} INFO - Executing <Task(BigQueryGetDataOperator): get_data> on 2024-06-22 21:57:35.049966+00:00
[2024-06-22T21:58:06.789+0000] {warnings.py:112} WARNING - /home/***/.local/lib/python3.12/site-packages/***/task/task_runner/standard_task_runner.py:61: DeprecationWarning: This process (pid=1204) is multi-threaded, use of fork() may lead to deadlocks in the child.
  pid = os.fork()

[2024-06-22T21:58:06.791+0000] {standard_task_runner.py:63} INFO - Started process 1207 to run task
[2024-06-22T21:58:06.790+0000] {standard_task_runner.py:90} INFO - Running: ['***', 'tasks', 'run', 'transform_data_dag', 'get_data', 'manual__2024-06-22T21:57:35.049966+00:00', '--job-id', '32', '--raw', '--subdir', 'DAGS_FOLDER/bigquery.py', '--cfg-path', '/tmp/tmpx_me4sk5']
[2024-06-22T21:58:06.795+0000] {standard_task_runner.py:91} INFO - Job 32: Subtask get_data
[2024-06-22T21:58:06.867+0000] {task_command.py:426} INFO - Running <TaskInstance: transform_data_dag.get_data manual__2024-06-22T21:57:35.049966+00:00 [running]> on host 64917a389d59
[2024-06-22T21:58:06.996+0000] {taskinstance.py:2648} INFO - Exporting env vars: AIRFLOW_CTX_DAG_OWNER='***' AIRFLOW_CTX_DAG_ID='transform_data_dag' AIRFLOW_CTX_TASK_ID='get_data' AIRFLOW_CTX_EXECUTION_DATE='2024-06-22T21:57:35.049966+00:00' AIRFLOW_CTX_TRY_NUMBER='1' AIRFLOW_CTX_DAG_RUN_ID='manual__2024-06-22T21:57:35.049966+00:00'
[2024-06-22T21:58:06.999+0000] {taskinstance.py:430} INFO - ::endgroup::
[2024-06-22T21:58:07.057+0000] {connection.py:274} WARNING - Connection schemes (type: google_cloud_platform) shall not contain '_' according to RFC3986.
[2024-06-22T21:58:07.061+0000] {base.py:84} INFO - Using connection ID 'google_cloud_default' for task execution.
[2024-06-22T21:58:07.169+0000] {bigquery.py:1046} INFO - Fetching Data from boreal-forest-427103-q9.transformed_1.test max results: 10
[2024-06-22T21:58:08.921+0000] {taskinstance.py:441} INFO - ::group::Post task execution logs
[2024-06-22T21:58:08.923+0000] {taskinstance.py:2905} ERROR - Task failed with exception
Traceback (most recent call last):
  File "/home/airflow/.local/lib/python3.12/site-packages/airflow/models/taskinstance.py", line 465, in _execute_task
    result = _execute_callable(context=context, **execute_callable_kwargs)
             ^^^^^^^^^^^^^^^^^^^^^^^^^^^^^^^^^^^^^^^^^^^^^^^^^^^^^^^^^^^^^
  File "/home/airflow/.local/lib/python3.12/site-packages/airflow/models/taskinstance.py", line 432, in _execute_callable
    return execute_callable(context=context, **execute_callable_kwargs)
           ^^^^^^^^^^^^^^^^^^^^^^^^^^^^^^^^^^^^^^^^^^^^^^^^^^^^^^^^^^^^
  File "/home/airflow/.local/lib/python3.12/site-packages/airflow/models/baseoperator.py", line 401, in wrapper
    return func(self, *args, **kwargs)
           ^^^^^^^^^^^^^^^^^^^^^^^^^^^
  File "/home/airflow/.local/lib/python3.12/site-packages/airflow/providers/google/cloud/operators/bigquery.py", line 1061, in execute
    rows: list[Row] | RowIterator | list[dict[str, Any]] = hook.list_rows(
                                                           ^^^^^^^^^^^^^^^
  File "/home/airflow/.local/lib/python3.12/site-packages/airflow/providers/google/common/hooks/base_google.py", line 528, in inner_wrapper
    return func(self, *args, **kwargs)
           ^^^^^^^^^^^^^^^^^^^^^^^^^^^
  File "/home/airflow/.local/lib/python3.12/site-packages/airflow/providers/google/cloud/hooks/bigquery.py", line 1396, in list_rows
    return list(iterator)
           ^^^^^^^^^^^^^^
  File "/home/airflow/.local/lib/python3.12/site-packages/google/api_core/page_iterator.py", line 208, in _items_iter
    for page in self._page_iter(increment=False):
  File "/home/airflow/.local/lib/python3.12/site-packages/google/api_core/page_iterator.py", line 244, in _page_iter
    page = self._next_page()
           ^^^^^^^^^^^^^^^^^
  File "/home/airflow/.local/lib/python3.12/site-packages/google/api_core/page_iterator.py", line 373, in _next_page
    response = self._get_next_page_response()
               ^^^^^^^^^^^^^^^^^^^^^^^^^^^^^^
  File "/home/airflow/.local/lib/python3.12/site-packages/google/cloud/bigquery/table.py", line 1744, in _get_next_page_response
    return self.api_request(
           ^^^^^^^^^^^^^^^^^
  File "/home/airflow/.local/lib/python3.12/site-packages/google/cloud/bigquery/client.py", line 833, in _call_api
    return call()
           ^^^^^^
  File "/home/airflow/.local/lib/python3.12/site-packages/google/api_core/retry/retry_unary.py", line 293, in retry_wrapped_func
    return retry_target(
           ^^^^^^^^^^^^^
  File "/home/airflow/.local/lib/python3.12/site-packages/google/api_core/retry/retry_unary.py", line 153, in retry_target
    _retry_error_helper(
  File "/home/airflow/.local/lib/python3.12/site-packages/google/api_core/retry/retry_base.py", line 212, in _retry_error_helper
    raise final_exc from source_exc
  File "/home/airflow/.local/lib/python3.12/site-packages/google/api_core/retry/retry_unary.py", line 144, in retry_target
    result = target()
             ^^^^^^^^
  File "/home/airflow/.local/lib/python3.12/site-packages/google/cloud/_http/__init__.py", line 494, in api_request
    raise exceptions.from_http_response(response)
google.api_core.exceptions.Forbidden: 403 GET https://bigquery.googleapis.com/bigquery/v2/projects/boreal-forest-427103-q9/datasets/transformed_1/tables/test/data?maxResults=10&selectedFields=value%2Cname&formatOptions.useInt64Timestamp=True&prettyPrint=false: Access Denied: Table boreal-forest-427103-q9:transformed_1.test: Permission bigquery.tables.getData denied on table boreal-forest-427103-q9:transformed_1.test (or it may not exist).
[2024-06-22T21:58:08.939+0000] {taskinstance.py:1206} INFO - Marking task as FAILED. dag_id=transform_data_dag, task_id=get_data, run_id=manual__2024-06-22T21:57:35.049966+00:00, execution_date=20240622T215735, start_date=20240622T215806, end_date=20240622T215808
[2024-06-22T21:58:08.959+0000] {standard_task_runner.py:110} ERROR - Failed to execute job 32 for task get_data (403 GET https://bigquery.googleapis.com/bigquery/v2/projects/boreal-forest-427103-q9/datasets/transformed_1/tables/test/data?maxResults=10&selectedFields=value%2Cname&formatOptions.useInt64Timestamp=True&prettyPrint=false: Access Denied: Table boreal-forest-427103-q9:transformed_1.test: Permission bigquery.tables.getData denied on table boreal-forest-427103-q9:transformed_1.test (or it may not exist).; 1207)
[2024-06-22T21:58:08.975+0000] {local_task_job_runner.py:240} INFO - Task exited with return code 1
[2024-06-22T21:58:08.994+0000] {taskinstance.py:3503} INFO - 0 downstream tasks scheduled from follow-on schedule check
[2024-06-22T21:58:08.998+0000] {local_task_job_runner.py:222} INFO - ::endgroup::
