[2024-06-23T03:02:32.136+0000] {local_task_job_runner.py:120} INFO - ::group::Pre task execution logs
[2024-06-23T03:02:32.155+0000] {taskinstance.py:2076} INFO - Dependencies all met for dep_context=non-requeueable deps ti=<TaskInstance: etl_pipeline_dag_with_encryption.decrypt_and_transform_data manual__2024-06-23T02:55:34.495783+00:00 [queued]>
[2024-06-23T03:02:32.164+0000] {taskinstance.py:2076} INFO - Dependencies all met for dep_context=requeueable deps ti=<TaskInstance: etl_pipeline_dag_with_encryption.decrypt_and_transform_data manual__2024-06-23T02:55:34.495783+00:00 [queued]>
[2024-06-23T03:02:32.165+0000] {taskinstance.py:2306} INFO - Starting attempt 1 of 4
[2024-06-23T03:02:32.181+0000] {taskinstance.py:2330} INFO - Executing <Task(PythonOperator): decrypt_and_transform_data> on 2024-06-23 02:55:34.495783+00:00
[2024-06-23T03:02:32.189+0000] {warnings.py:112} WARNING - /home/***/.local/lib/python3.12/site-packages/***/task/task_runner/standard_task_runner.py:61: DeprecationWarning: This process (pid=4934) is multi-threaded, use of fork() may lead to deadlocks in the child.
  pid = os.fork()

[2024-06-23T03:02:32.191+0000] {standard_task_runner.py:63} INFO - Started process 4936 to run task
[2024-06-23T03:02:32.191+0000] {standard_task_runner.py:90} INFO - Running: ['***', 'tasks', 'run', 'etl_pipeline_dag_with_encryption', 'decrypt_and_transform_data', 'manual__2024-06-23T02:55:34.495783+00:00', '--job-id', '86', '--raw', '--subdir', 'DAGS_FOLDER/bigquery.py', '--cfg-path', '/tmp/tmpwlpx4d92']
[2024-06-23T03:02:32.194+0000] {standard_task_runner.py:91} INFO - Job 86: Subtask decrypt_and_transform_data
[2024-06-23T03:02:32.247+0000] {task_command.py:426} INFO - Running <TaskInstance: etl_pipeline_dag_with_encryption.decrypt_and_transform_data manual__2024-06-23T02:55:34.495783+00:00 [running]> on host 64917a389d59
[2024-06-23T03:02:32.344+0000] {taskinstance.py:2648} INFO - Exporting env vars: AIRFLOW_CTX_DAG_OWNER='***' AIRFLOW_CTX_DAG_ID='etl_pipeline_dag_with_encryption' AIRFLOW_CTX_TASK_ID='decrypt_and_transform_data' AIRFLOW_CTX_EXECUTION_DATE='2024-06-23T02:55:34.495783+00:00' AIRFLOW_CTX_TRY_NUMBER='1' AIRFLOW_CTX_DAG_RUN_ID='manual__2024-06-23T02:55:34.495783+00:00'
[2024-06-23T03:02:32.346+0000] {taskinstance.py:430} INFO - ::endgroup::
[2024-06-23T03:02:32.364+0000] {taskinstance.py:441} INFO - ::group::Post task execution logs
[2024-06-23T03:02:32.365+0000] {taskinstance.py:2905} ERROR - Task failed with exception
Traceback (most recent call last):
  File "/home/airflow/.local/lib/python3.12/site-packages/cryptography/fernet.py", line 134, in _verify_signature
    h.verify(data[-32:])
cryptography.exceptions.InvalidSignature: Signature did not match digest.

During handling of the above exception, another exception occurred:

Traceback (most recent call last):
  File "/home/airflow/.local/lib/python3.12/site-packages/airflow/models/taskinstance.py", line 465, in _execute_task
    result = _execute_callable(context=context, **execute_callable_kwargs)
             ^^^^^^^^^^^^^^^^^^^^^^^^^^^^^^^^^^^^^^^^^^^^^^^^^^^^^^^^^^^^^
  File "/home/airflow/.local/lib/python3.12/site-packages/airflow/models/taskinstance.py", line 432, in _execute_callable
    return execute_callable(context=context, **execute_callable_kwargs)
           ^^^^^^^^^^^^^^^^^^^^^^^^^^^^^^^^^^^^^^^^^^^^^^^^^^^^^^^^^^^^
  File "/home/airflow/.local/lib/python3.12/site-packages/airflow/models/baseoperator.py", line 401, in wrapper
    return func(self, *args, **kwargs)
           ^^^^^^^^^^^^^^^^^^^^^^^^^^^
  File "/home/airflow/.local/lib/python3.12/site-packages/airflow/operators/python.py", line 235, in execute
    return_value = self.execute_callable()
                   ^^^^^^^^^^^^^^^^^^^^^^^
  File "/home/airflow/.local/lib/python3.12/site-packages/airflow/operators/python.py", line 252, in execute_callable
    return self.python_callable(*self.op_args, **self.op_kwargs)
           ^^^^^^^^^^^^^^^^^^^^^^^^^^^^^^^^^^^^^^^^^^^^^^^^^^^^^
  File "/opt/airflow/dags/bigquery.py", line 49, in decrypt_and_transform_data
    decrypted_data = fernet.decrypt(encrypted_data)
                     ^^^^^^^^^^^^^^^^^^^^^^^^^^^^^^
  File "/home/airflow/.local/lib/python3.12/site-packages/cryptography/fernet.py", line 91, in decrypt
    return self._decrypt_data(data, timestamp, time_info)
           ^^^^^^^^^^^^^^^^^^^^^^^^^^^^^^^^^^^^^^^^^^^^^^
  File "/home/airflow/.local/lib/python3.12/site-packages/cryptography/fernet.py", line 152, in _decrypt_data
    self._verify_signature(data)
  File "/home/airflow/.local/lib/python3.12/site-packages/cryptography/fernet.py", line 136, in _verify_signature
    raise InvalidToken
cryptography.fernet.InvalidToken
[2024-06-23T03:02:32.384+0000] {taskinstance.py:1206} INFO - Marking task as UP_FOR_RETRY. dag_id=etl_pipeline_dag_with_encryption, task_id=decrypt_and_transform_data, run_id=manual__2024-06-23T02:55:34.495783+00:00, execution_date=20240623T025534, start_date=20240623T030232, end_date=20240623T030232
[2024-06-23T03:02:32.397+0000] {standard_task_runner.py:110} ERROR - Failed to execute job 86 for task decrypt_and_transform_data (; 4936)
[2024-06-23T03:02:32.446+0000] {local_task_job_runner.py:240} INFO - Task exited with return code 1
[2024-06-23T03:02:32.478+0000] {taskinstance.py:3503} INFO - 0 downstream tasks scheduled from follow-on schedule check
[2024-06-23T03:02:32.481+0000] {local_task_job_runner.py:222} INFO - ::endgroup::
