[2024-06-22T06:36:47.665+0000] {local_task_job_runner.py:120} INFO - ::group::Pre task execution logs
[2024-06-22T06:36:47.700+0000] {taskinstance.py:2076} INFO - Dependencies all met for dep_context=non-requeueable deps ti=<TaskInstance: gcs_processing.etl_process manual__2024-06-22T06:31:26.309100+00:00 [queued]>
[2024-06-22T06:36:47.718+0000] {taskinstance.py:2076} INFO - Dependencies all met for dep_context=requeueable deps ti=<TaskInstance: gcs_processing.etl_process manual__2024-06-22T06:31:26.309100+00:00 [queued]>
[2024-06-22T06:36:47.719+0000] {taskinstance.py:2306} INFO - Starting attempt 2 of 2
[2024-06-22T06:36:47.746+0000] {taskinstance.py:2330} INFO - Executing <Task(PythonOperator): etl_process> on 2024-06-22 06:31:26.309100+00:00
[2024-06-22T06:36:47.768+0000] {warnings.py:112} WARNING - /home/***/.local/lib/python3.12/site-packages/***/task/task_runner/standard_task_runner.py:61: DeprecationWarning: This process (pid=1904) is multi-threaded, use of fork() may lead to deadlocks in the child.
  pid = os.fork()

[2024-06-22T06:36:47.772+0000] {standard_task_runner.py:63} INFO - Started process 1906 to run task
[2024-06-22T06:36:47.771+0000] {standard_task_runner.py:90} INFO - Running: ['***', 'tasks', 'run', 'gcs_processing', 'etl_process', 'manual__2024-06-22T06:31:26.309100+00:00', '--job-id', '14', '--raw', '--subdir', 'DAGS_FOLDER/gcs_processing.py', '--cfg-path', '/tmp/tmp3_0ljgxg']
[2024-06-22T06:36:47.777+0000] {standard_task_runner.py:91} INFO - Job 14: Subtask etl_process
[2024-06-22T06:36:47.899+0000] {task_command.py:426} INFO - Running <TaskInstance: gcs_processing.etl_process manual__2024-06-22T06:31:26.309100+00:00 [running]> on host ef7fea064a97
[2024-06-22T06:36:48.032+0000] {taskinstance.py:2648} INFO - Exporting env vars: AIRFLOW_CTX_DAG_OWNER='***' AIRFLOW_CTX_DAG_ID='gcs_processing' AIRFLOW_CTX_TASK_ID='etl_process' AIRFLOW_CTX_EXECUTION_DATE='2024-06-22T06:31:26.309100+00:00' AIRFLOW_CTX_TRY_NUMBER='2' AIRFLOW_CTX_DAG_RUN_ID='manual__2024-06-22T06:31:26.309100+00:00'
[2024-06-22T06:36:48.034+0000] {taskinstance.py:430} INFO - ::endgroup::
[2024-06-22T06:36:48.087+0000] {taskinstance.py:441} INFO - ::group::Post task execution logs
[2024-06-22T06:36:48.106+0000] {taskinstance.py:2905} ERROR - Task failed with exception
Traceback (most recent call last):
  File "/home/airflow/.local/lib/python3.12/site-packages/airflow/models/taskinstance.py", line 465, in _execute_task
    result = _execute_callable(context=context, **execute_callable_kwargs)
             ^^^^^^^^^^^^^^^^^^^^^^^^^^^^^^^^^^^^^^^^^^^^^^^^^^^^^^^^^^^^^
  File "/home/airflow/.local/lib/python3.12/site-packages/airflow/models/taskinstance.py", line 432, in _execute_callable
    return execute_callable(context=context, **execute_callable_kwargs)
           ^^^^^^^^^^^^^^^^^^^^^^^^^^^^^^^^^^^^^^^^^^^^^^^^^^^^^^^^^^^^
  File "/home/airflow/.local/lib/python3.12/site-packages/airflow/models/baseoperator.py", line 401, in wrapper
    return func(self, *args, **kwargs)
           ^^^^^^^^^^^^^^^^^^^^^^^^^^^
  File "/home/airflow/.local/lib/python3.12/site-packages/airflow/operators/python.py", line 235, in execute
    return_value = self.execute_callable()
                   ^^^^^^^^^^^^^^^^^^^^^^^
  File "/home/airflow/.local/lib/python3.12/site-packages/airflow/operators/python.py", line 252, in execute_callable
    return self.python_callable(*self.op_args, **self.op_kwargs)
           ^^^^^^^^^^^^^^^^^^^^^^^^^^^^^^^^^^^^^^^^^^^^^^^^^^^^^
  File "/opt/airflow/dags/gcs_processing.py", line 12, in etl_process
    gcs_hook = GCSHook(gcp_conn_id='google_cloud_default', key_path=key_path)
               ^^^^^^^^^^^^^^^^^^^^^^^^^^^^^^^^^^^^^^^^^^^^^^^^^^^^^^^^^^^^^^
  File "/home/airflow/.local/lib/python3.12/site-packages/airflow/providers/google/cloud/hooks/gcs.py", line 164, in __init__
    super().__init__(
  File "/home/airflow/.local/lib/python3.12/site-packages/airflow/providers/google/common/hooks/base_google.py", line 274, in __init__
    self.extras: dict = self.get_connection(self.gcp_conn_id).extra_dejson
                        ^^^^^^^^^^^^^^^^^^^^^^^^^^^^^^^^^^^^^
  File "/home/airflow/.local/lib/python3.12/site-packages/airflow/hooks/base.py", line 83, in get_connection
    conn = Connection.get_connection_from_secrets(conn_id)
           ^^^^^^^^^^^^^^^^^^^^^^^^^^^^^^^^^^^^^^^^^^^^^^^
  File "/home/airflow/.local/lib/python3.12/site-packages/airflow/models/connection.py", line 519, in get_connection_from_secrets
    raise AirflowNotFoundException(f"The conn_id `{conn_id}` isn't defined")
airflow.exceptions.AirflowNotFoundException: The conn_id `google_cloud_default` isn't defined
[2024-06-22T06:36:48.132+0000] {taskinstance.py:1206} INFO - Marking task as FAILED. dag_id=gcs_processing, task_id=etl_process, run_id=manual__2024-06-22T06:31:26.309100+00:00, execution_date=20240622T063126, start_date=20240622T063647, end_date=20240622T063648
[2024-06-22T06:36:48.160+0000] {standard_task_runner.py:110} ERROR - Failed to execute job 14 for task etl_process (The conn_id `google_cloud_default` isn't defined; 1906)
[2024-06-22T06:36:48.190+0000] {local_task_job_runner.py:240} INFO - Task exited with return code 1
[2024-06-22T06:36:48.213+0000] {local_task_job_runner.py:222} INFO - ::endgroup::
